Watching for file changes with StatReloader
Performing system checks...

System check identified no issues (0 silenced).
September 18, 2025 - 11:39:01
Django version 3.2.16, using settings 'interview_system.settings'
Starting development server at http://0.0.0.0:8000/
Quit the server with CONTROL-C.
[18/Sep/2025 11:39:10] "GET /admin/interviews/company/ HTTP/1.1" 200 8802
[18/Sep/2025 11:39:11] "GET /static/admin/css/base.css HTTP/1.1" 304 0
[18/Sep/2025 11:39:11] "GET /static/admin/css/nav_sidebar.css HTTP/1.1" 304 0
[18/Sep/2025 11:39:11] "GET /static/admin/css/changelists.css HTTP/1.1" 304 0
[18/Sep/2025 11:39:11] "GET /static/admin/css/responsive.css HTTP/1.1" 304 0
[18/Sep/2025 11:39:11] "GET /static/admin/js/vendor/jquery/jquery.js HTTP/1.1" 304 0
[18/Sep/2025 11:39:11] "GET /admin/jsi18n/ HTTP/1.1" 200 8398
[18/Sep/2025 11:39:11] "GET /static/admin/js/jquery.init.js HTTP/1.1" 304 0
[18/Sep/2025 11:39:11] "GET /static/admin/js/admin/RelatedObjectLookups.js HTTP/1.1" 304 0
[18/Sep/2025 11:39:11] "GET /static/admin/js/core.js HTTP/1.1" 304 0
[18/Sep/2025 11:39:11] "GET /static/admin/js/actions.js HTTP/1.1" 304 0
[18/Sep/2025 11:39:11] "GET /static/admin/js/urlify.js HTTP/1.1" 304 0
[18/Sep/2025 11:39:11] "GET /static/admin/css/fonts.css HTTP/1.1" 304 0
[18/Sep/2025 11:39:11] "GET /static/admin/js/prepopulate.js HTTP/1.1" 304 0
[18/Sep/2025 11:39:11] "GET /static/admin/js/vendor/xregexp/xregexp.js HTTP/1.1" 304 0
[18/Sep/2025 11:39:11] "GET /static/admin/img/search.svg HTTP/1.1" 304 0
[18/Sep/2025 11:39:11] "GET /static/admin/js/nav_sidebar.js HTTP/1.1" 304 0
[18/Sep/2025 11:39:11] "GET /static/admin/img/icon-addlink.svg HTTP/1.1" 304 0
[18/Sep/2025 11:39:11] "GET /static/admin/img/tooltag-add.svg HTTP/1.1" 304 0
[18/Sep/2025 11:39:11] "GET /static/admin/fonts/Roboto-Bold-webfont.woff HTTP/1.1" 304 0
[18/Sep/2025 11:39:11] "GET /static/admin/fonts/Roboto-Regular-webfont.woff HTTP/1.1" 304 0
[18/Sep/2025 11:39:11] "GET /static/admin/fonts/Roboto-Light-webfont.woff HTTP/1.1" 304 0
[18/Sep/2025 11:39:15] "GET /admin/interviews/interview/ HTTP/1.1" 200 15118
[18/Sep/2025 11:39:15] "GET /admin/jsi18n/ HTTP/1.1" 200 8398
[18/Sep/2025 11:39:15] "GET /static/admin/img/icon-no.svg HTTP/1.1" 304 0
[18/Sep/2025 11:39:15] "GET /static/admin/img/sorting-icons.svg HTTP/1.1" 304 0
[18/Sep/2025 11:42:23] "GET /api/dashboard/stats/ HTTP/1.1" 200 249
[18/Sep/2025 11:42:23] "GET /api/interviews/ HTTP/1.1" 200 4338
[18/Sep/2025 11:42:28] "GET /api/companies/ HTTP/1.1" 200 365
[18/Sep/2025 11:42:28] "GET /api/positions/ HTTP/1.1" 200 1079
Internal Server Error: /api/interviews/
Traceback (most recent call last):
  File "/usr/local/lib/python3.10/dist-packages/django/db/backends/utils.py", line 84, in _execute
    return self.cursor.execute(sql, params)
  File "/usr/local/lib/python3.10/dist-packages/django/db/backends/sqlite3/base.py", line 423, in execute
    return Database.Cursor.execute(self, query, params)
sqlite3.IntegrityError: NOT NULL constraint failed: interviews_interview.interviewer_id

The above exception was the direct cause of the following exception:

Traceback (most recent call last):
  File "/usr/local/lib/python3.10/dist-packages/django/core/handlers/exception.py", line 47, in inner
    response = get_response(request)
  File "/usr/local/lib/python3.10/dist-packages/django/core/handlers/base.py", line 181, in _get_response
    response = wrapped_callback(request, *callback_args, **callback_kwargs)
  File "/usr/local/lib/python3.10/dist-packages/django/views/decorators/csrf.py", line 54, in wrapped_view
    return view_func(*args, **kwargs)
  File "/usr/local/lib/python3.10/dist-packages/rest_framework/viewsets.py", line 125, in view
    return self.dispatch(request, *args, **kwargs)
  File "/usr/local/lib/python3.10/dist-packages/rest_framework/views.py", line 509, in dispatch
    response = self.handle_exception(exc)
  File "/usr/local/lib/python3.10/dist-packages/rest_framework/views.py", line 469, in handle_exception
    self.raise_uncaught_exception(exc)
  File "/usr/local/lib/python3.10/dist-packages/rest_framework/views.py", line 480, in raise_uncaught_exception
    raise exc
  File "/usr/local/lib/python3.10/dist-packages/rest_framework/views.py", line 506, in dispatch
    response = handler(request, *args, **kwargs)
  File "/usr/local/lib/python3.10/dist-packages/rest_framework/mixins.py", line 19, in create
    self.perform_create(serializer)
  File "/usr/local/lib/python3.10/dist-packages/rest_framework/mixins.py", line 24, in perform_create
    serializer.save()
  File "/usr/local/lib/python3.10/dist-packages/rest_framework/serializers.py", line 212, in save
    self.instance = self.create(validated_data)
  File "/usr/local/lib/python3.10/dist-packages/rest_framework/serializers.py", line 962, in create
    instance = ModelClass._default_manager.create(**validated_data)
  File "/usr/local/lib/python3.10/dist-packages/django/db/models/manager.py", line 85, in manager_method
    return getattr(self.get_queryset(), name)(*args, **kwargs)
  File "/usr/local/lib/python3.10/dist-packages/django/db/models/query.py", line 453, in create
    obj.save(force_insert=True, using=self.db)
  File "/home/james/abc/backend/interviews/models.py", line 137, in save
    super().save(*args, **kwargs)
  File "/usr/local/lib/python3.10/dist-packages/django/db/models/base.py", line 739, in save
    self.save_base(using=using, force_insert=force_insert,
  File "/usr/local/lib/python3.10/dist-packages/django/db/models/base.py", line 776, in save_base
    updated = self._save_table(
  File "/usr/local/lib/python3.10/dist-packages/django/db/models/base.py", line 881, in _save_table
    results = self._do_insert(cls._base_manager, using, fields, returning_fields, raw)
  File "/usr/local/lib/python3.10/dist-packages/django/db/models/base.py", line 919, in _do_insert
    return manager._insert(
  File "/usr/local/lib/python3.10/dist-packages/django/db/models/manager.py", line 85, in manager_method
    return getattr(self.get_queryset(), name)(*args, **kwargs)
  File "/usr/local/lib/python3.10/dist-packages/django/db/models/query.py", line 1270, in _insert
    return query.get_compiler(using=using).execute_sql(returning_fields)
  File "/usr/local/lib/python3.10/dist-packages/django/db/models/sql/compiler.py", line 1416, in execute_sql
    cursor.execute(sql, params)
  File "/usr/local/lib/python3.10/dist-packages/django/db/backends/utils.py", line 98, in execute
    return super().execute(sql, params)
  File "/usr/local/lib/python3.10/dist-packages/django/db/backends/utils.py", line 66, in execute
    return self._execute_with_wrappers(sql, params, many=False, executor=self._execute)
  File "/usr/local/lib/python3.10/dist-packages/django/db/backends/utils.py", line 75, in _execute_with_wrappers
    return executor(sql, params, many, context)
  File "/usr/local/lib/python3.10/dist-packages/django/db/backends/utils.py", line 79, in _execute
    with self.db.wrap_database_errors:
  File "/usr/local/lib/python3.10/dist-packages/django/db/utils.py", line 90, in __exit__
    raise dj_exc_value.with_traceback(traceback) from exc_value
  File "/usr/local/lib/python3.10/dist-packages/django/db/backends/utils.py", line 84, in _execute
    return self.cursor.execute(sql, params)
  File "/usr/local/lib/python3.10/dist-packages/django/db/backends/sqlite3/base.py", line 423, in execute
    return Database.Cursor.execute(self, query, params)
django.db.utils.IntegrityError: NOT NULL constraint failed: interviews_interview.interviewer_id
[18/Sep/2025 11:43:00] "POST /api/interviews/ HTTP/1.1" 500 222558
Internal Server Error: /api/interviews/
Traceback (most recent call last):
  File "/usr/local/lib/python3.10/dist-packages/django/db/backends/utils.py", line 84, in _execute
    return self.cursor.execute(sql, params)
  File "/usr/local/lib/python3.10/dist-packages/django/db/backends/sqlite3/base.py", line 423, in execute
    return Database.Cursor.execute(self, query, params)
sqlite3.IntegrityError: NOT NULL constraint failed: interviews_interview.interviewer_id

The above exception was the direct cause of the following exception:

Traceback (most recent call last):
  File "/usr/local/lib/python3.10/dist-packages/django/core/handlers/exception.py", line 47, in inner
    response = get_response(request)
  File "/usr/local/lib/python3.10/dist-packages/django/core/handlers/base.py", line 181, in _get_response
    response = wrapped_callback(request, *callback_args, **callback_kwargs)
  File "/usr/local/lib/python3.10/dist-packages/django/views/decorators/csrf.py", line 54, in wrapped_view
    return view_func(*args, **kwargs)
  File "/usr/local/lib/python3.10/dist-packages/rest_framework/viewsets.py", line 125, in view
    return self.dispatch(request, *args, **kwargs)
  File "/usr/local/lib/python3.10/dist-packages/rest_framework/views.py", line 509, in dispatch
    response = self.handle_exception(exc)
  File "/usr/local/lib/python3.10/dist-packages/rest_framework/views.py", line 469, in handle_exception
    self.raise_uncaught_exception(exc)
  File "/usr/local/lib/python3.10/dist-packages/rest_framework/views.py", line 480, in raise_uncaught_exception
    raise exc
  File "/usr/local/lib/python3.10/dist-packages/rest_framework/views.py", line 506, in dispatch
    response = handler(request, *args, **kwargs)
  File "/usr/local/lib/python3.10/dist-packages/rest_framework/mixins.py", line 19, in create
    self.perform_create(serializer)
  File "/usr/local/lib/python3.10/dist-packages/rest_framework/mixins.py", line 24, in perform_create
    serializer.save()
  File "/usr/local/lib/python3.10/dist-packages/rest_framework/serializers.py", line 212, in save
    self.instance = self.create(validated_data)
  File "/usr/local/lib/python3.10/dist-packages/rest_framework/serializers.py", line 962, in create
    instance = ModelClass._default_manager.create(**validated_data)
  File "/usr/local/lib/python3.10/dist-packages/django/db/models/manager.py", line 85, in manager_method
    return getattr(self.get_queryset(), name)(*args, **kwargs)
  File "/usr/local/lib/python3.10/dist-packages/django/db/models/query.py", line 453, in create
    obj.save(force_insert=True, using=self.db)
  File "/home/james/abc/backend/interviews/models.py", line 137, in save
    super().save(*args, **kwargs)
  File "/usr/local/lib/python3.10/dist-packages/django/db/models/base.py", line 739, in save
    self.save_base(using=using, force_insert=force_insert,
  File "/usr/local/lib/python3.10/dist-packages/django/db/models/base.py", line 776, in save_base
    updated = self._save_table(
  File "/usr/local/lib/python3.10/dist-packages/django/db/models/base.py", line 881, in _save_table
    results = self._do_insert(cls._base_manager, using, fields, returning_fields, raw)
  File "/usr/local/lib/python3.10/dist-packages/django/db/models/base.py", line 919, in _do_insert
    return manager._insert(
  File "/usr/local/lib/python3.10/dist-packages/django/db/models/manager.py", line 85, in manager_method
    return getattr(self.get_queryset(), name)(*args, **kwargs)
  File "/usr/local/lib/python3.10/dist-packages/django/db/models/query.py", line 1270, in _insert
    return query.get_compiler(using=using).execute_sql(returning_fields)
  File "/usr/local/lib/python3.10/dist-packages/django/db/models/sql/compiler.py", line 1416, in execute_sql
    cursor.execute(sql, params)
  File "/usr/local/lib/python3.10/dist-packages/django/db/backends/utils.py", line 98, in execute
    return super().execute(sql, params)
  File "/usr/local/lib/python3.10/dist-packages/django/db/backends/utils.py", line 66, in execute
    return self._execute_with_wrappers(sql, params, many=False, executor=self._execute)
  File "/usr/local/lib/python3.10/dist-packages/django/db/backends/utils.py", line 75, in _execute_with_wrappers
    return executor(sql, params, many, context)
  File "/usr/local/lib/python3.10/dist-packages/django/db/backends/utils.py", line 79, in _execute
    with self.db.wrap_database_errors:
  File "/usr/local/lib/python3.10/dist-packages/django/db/utils.py", line 90, in __exit__
    raise dj_exc_value.with_traceback(traceback) from exc_value
  File "/usr/local/lib/python3.10/dist-packages/django/db/backends/utils.py", line 84, in _execute
    return self.cursor.execute(sql, params)
  File "/usr/local/lib/python3.10/dist-packages/django/db/backends/sqlite3/base.py", line 423, in execute
    return Database.Cursor.execute(self, query, params)
django.db.utils.IntegrityError: NOT NULL constraint failed: interviews_interview.interviewer_id
[18/Sep/2025 11:44:19] "POST /api/interviews/ HTTP/1.1" 500 222558
[18/Sep/2025 11:44:27] "GET /api/interviews HTTP/1.1" 301 0
[18/Sep/2025 11:44:28] "GET /api/interviews/ HTTP/1.1" 200 27165
[18/Sep/2025 11:44:28] "GET /static/rest_framework/css/bootstrap.min.css HTTP/1.1" 304 0
[18/Sep/2025 11:44:28] "GET /static/rest_framework/css/bootstrap-tweaks.css HTTP/1.1" 304 0
[18/Sep/2025 11:44:28] "GET /static/rest_framework/css/prettify.css HTTP/1.1" 304 0
[18/Sep/2025 11:44:28] "GET /static/rest_framework/css/default.css HTTP/1.1" 304 0
[18/Sep/2025 11:44:28] "GET /static/rest_framework/js/ajax-form.js HTTP/1.1" 304 0
[18/Sep/2025 11:44:28] "GET /static/rest_framework/js/jquery-3.5.1.min.js HTTP/1.1" 304 0
[18/Sep/2025 11:44:28] "GET /static/rest_framework/js/csrf.js HTTP/1.1" 304 0
[18/Sep/2025 11:44:28] "GET /static/rest_framework/js/bootstrap.min.js HTTP/1.1" 304 0
[18/Sep/2025 11:44:28] "GET /static/rest_framework/js/prettify-min.js HTTP/1.1" 304 0
[18/Sep/2025 11:44:28] "GET /static/rest_framework/js/default.js HTTP/1.1" 304 0
[18/Sep/2025 11:44:28] "GET /static/rest_framework/img/grid.png HTTP/1.1" 304 0
[18/Sep/2025 11:51:13] "GET /api/dashboard/stats/ HTTP/1.1" 200 249
[18/Sep/2025 11:51:13] "GET /api/interviews/ HTTP/1.1" 200 4338
[18/Sep/2025 11:51:17] "GET /api/companies/ HTTP/1.1" 200 365
[18/Sep/2025 11:51:17] "GET /api/positions/ HTTP/1.1" 200 1079
Internal Server Error: /api/interviews/
Traceback (most recent call last):
  File "/usr/local/lib/python3.10/dist-packages/django/db/backends/utils.py", line 84, in _execute
    return self.cursor.execute(sql, params)
  File "/usr/local/lib/python3.10/dist-packages/django/db/backends/sqlite3/base.py", line 423, in execute
    return Database.Cursor.execute(self, query, params)
sqlite3.IntegrityError: NOT NULL constraint failed: interviews_interview.interviewer_id

The above exception was the direct cause of the following exception:

Traceback (most recent call last):
  File "/usr/local/lib/python3.10/dist-packages/django/core/handlers/exception.py", line 47, in inner
    response = get_response(request)
  File "/usr/local/lib/python3.10/dist-packages/django/core/handlers/base.py", line 181, in _get_response
    response = wrapped_callback(request, *callback_args, **callback_kwargs)
  File "/usr/local/lib/python3.10/dist-packages/django/views/decorators/csrf.py", line 54, in wrapped_view
    return view_func(*args, **kwargs)
  File "/usr/local/lib/python3.10/dist-packages/rest_framework/viewsets.py", line 125, in view
    return self.dispatch(request, *args, **kwargs)
  File "/usr/local/lib/python3.10/dist-packages/rest_framework/views.py", line 509, in dispatch
    response = self.handle_exception(exc)
  File "/usr/local/lib/python3.10/dist-packages/rest_framework/views.py", line 469, in handle_exception
    self.raise_uncaught_exception(exc)
  File "/usr/local/lib/python3.10/dist-packages/rest_framework/views.py", line 480, in raise_uncaught_exception
    raise exc
  File "/usr/local/lib/python3.10/dist-packages/rest_framework/views.py", line 506, in dispatch
    response = handler(request, *args, **kwargs)
  File "/usr/local/lib/python3.10/dist-packages/rest_framework/mixins.py", line 19, in create
    self.perform_create(serializer)
  File "/usr/local/lib/python3.10/dist-packages/rest_framework/mixins.py", line 24, in perform_create
    serializer.save()
  File "/usr/local/lib/python3.10/dist-packages/rest_framework/serializers.py", line 212, in save
    self.instance = self.create(validated_data)
  File "/usr/local/lib/python3.10/dist-packages/rest_framework/serializers.py", line 962, in create
    instance = ModelClass._default_manager.create(**validated_data)
  File "/usr/local/lib/python3.10/dist-packages/django/db/models/manager.py", line 85, in manager_method
    return getattr(self.get_queryset(), name)(*args, **kwargs)
  File "/usr/local/lib/python3.10/dist-packages/django/db/models/query.py", line 453, in create
    obj.save(force_insert=True, using=self.db)
  File "/home/james/abc/backend/interviews/models.py", line 137, in save
    super().save(*args, **kwargs)
  File "/usr/local/lib/python3.10/dist-packages/django/db/models/base.py", line 739, in save
    self.save_base(using=using, force_insert=force_insert,
  File "/usr/local/lib/python3.10/dist-packages/django/db/models/base.py", line 776, in save_base
    updated = self._save_table(
  File "/usr/local/lib/python3.10/dist-packages/django/db/models/base.py", line 881, in _save_table
    results = self._do_insert(cls._base_manager, using, fields, returning_fields, raw)
  File "/usr/local/lib/python3.10/dist-packages/django/db/models/base.py", line 919, in _do_insert
    return manager._insert(
  File "/usr/local/lib/python3.10/dist-packages/django/db/models/manager.py", line 85, in manager_method
    return getattr(self.get_queryset(), name)(*args, **kwargs)
  File "/usr/local/lib/python3.10/dist-packages/django/db/models/query.py", line 1270, in _insert
    return query.get_compiler(using=using).execute_sql(returning_fields)
  File "/usr/local/lib/python3.10/dist-packages/django/db/models/sql/compiler.py", line 1416, in execute_sql
    cursor.execute(sql, params)
  File "/usr/local/lib/python3.10/dist-packages/django/db/backends/utils.py", line 98, in execute
    return super().execute(sql, params)
  File "/usr/local/lib/python3.10/dist-packages/django/db/backends/utils.py", line 66, in execute
    return self._execute_with_wrappers(sql, params, many=False, executor=self._execute)
  File "/usr/local/lib/python3.10/dist-packages/django/db/backends/utils.py", line 75, in _execute_with_wrappers
    return executor(sql, params, many, context)
  File "/usr/local/lib/python3.10/dist-packages/django/db/backends/utils.py", line 79, in _execute
    with self.db.wrap_database_errors:
  File "/usr/local/lib/python3.10/dist-packages/django/db/utils.py", line 90, in __exit__
    raise dj_exc_value.with_traceback(traceback) from exc_value
  File "/usr/local/lib/python3.10/dist-packages/django/db/backends/utils.py", line 84, in _execute
    return self.cursor.execute(sql, params)
  File "/usr/local/lib/python3.10/dist-packages/django/db/backends/sqlite3/base.py", line 423, in execute
    return Database.Cursor.execute(self, query, params)
django.db.utils.IntegrityError: NOT NULL constraint failed: interviews_interview.interviewer_id
[18/Sep/2025 11:52:31] "POST /api/interviews/ HTTP/1.1" 500 222606
Internal Server Error: /api/interviews/
Traceback (most recent call last):
  File "/usr/local/lib/python3.10/dist-packages/django/db/backends/utils.py", line 84, in _execute
    return self.cursor.execute(sql, params)
  File "/usr/local/lib/python3.10/dist-packages/django/db/backends/sqlite3/base.py", line 423, in execute
    return Database.Cursor.execute(self, query, params)
sqlite3.IntegrityError: NOT NULL constraint failed: interviews_interview.interviewer_id

The above exception was the direct cause of the following exception:

Traceback (most recent call last):
  File "/usr/local/lib/python3.10/dist-packages/django/core/handlers/exception.py", line 47, in inner
    response = get_response(request)
  File "/usr/local/lib/python3.10/dist-packages/django/core/handlers/base.py", line 181, in _get_response
    response = wrapped_callback(request, *callback_args, **callback_kwargs)
  File "/usr/local/lib/python3.10/dist-packages/django/views/decorators/csrf.py", line 54, in wrapped_view
    return view_func(*args, **kwargs)
  File "/usr/local/lib/python3.10/dist-packages/rest_framework/viewsets.py", line 125, in view
    return self.dispatch(request, *args, **kwargs)
  File "/usr/local/lib/python3.10/dist-packages/rest_framework/views.py", line 509, in dispatch
    response = self.handle_exception(exc)
  File "/usr/local/lib/python3.10/dist-packages/rest_framework/views.py", line 469, in handle_exception
    self.raise_uncaught_exception(exc)
  File "/usr/local/lib/python3.10/dist-packages/rest_framework/views.py", line 480, in raise_uncaught_exception
    raise exc
  File "/usr/local/lib/python3.10/dist-packages/rest_framework/views.py", line 506, in dispatch
    response = handler(request, *args, **kwargs)
  File "/usr/local/lib/python3.10/dist-packages/rest_framework/mixins.py", line 19, in create
    self.perform_create(serializer)
  File "/usr/local/lib/python3.10/dist-packages/rest_framework/mixins.py", line 24, in perform_create
    serializer.save()
  File "/usr/local/lib/python3.10/dist-packages/rest_framework/serializers.py", line 212, in save
    self.instance = self.create(validated_data)
  File "/usr/local/lib/python3.10/dist-packages/rest_framework/serializers.py", line 962, in create
    instance = ModelClass._default_manager.create(**validated_data)
  File "/usr/local/lib/python3.10/dist-packages/django/db/models/manager.py", line 85, in manager_method
    return getattr(self.get_queryset(), name)(*args, **kwargs)
  File "/usr/local/lib/python3.10/dist-packages/django/db/models/query.py", line 453, in create
    obj.save(force_insert=True, using=self.db)
  File "/home/james/abc/backend/interviews/models.py", line 137, in save
    super().save(*args, **kwargs)
  File "/usr/local/lib/python3.10/dist-packages/django/db/models/base.py", line 739, in save
    self.save_base(using=using, force_insert=force_insert,
  File "/usr/local/lib/python3.10/dist-packages/django/db/models/base.py", line 776, in save_base
    updated = self._save_table(
  File "/usr/local/lib/python3.10/dist-packages/django/db/models/base.py", line 881, in _save_table
    results = self._do_insert(cls._base_manager, using, fields, returning_fields, raw)
  File "/usr/local/lib/python3.10/dist-packages/django/db/models/base.py", line 919, in _do_insert
    return manager._insert(
  File "/usr/local/lib/python3.10/dist-packages/django/db/models/manager.py", line 85, in manager_method
    return getattr(self.get_queryset(), name)(*args, **kwargs)
  File "/usr/local/lib/python3.10/dist-packages/django/db/models/query.py", line 1270, in _insert
    return query.get_compiler(using=using).execute_sql(returning_fields)
  File "/usr/local/lib/python3.10/dist-packages/django/db/models/sql/compiler.py", line 1416, in execute_sql
    cursor.execute(sql, params)
  File "/usr/local/lib/python3.10/dist-packages/django/db/backends/utils.py", line 98, in execute
    return super().execute(sql, params)
  File "/usr/local/lib/python3.10/dist-packages/django/db/backends/utils.py", line 66, in execute
    return self._execute_with_wrappers(sql, params, many=False, executor=self._execute)
  File "/usr/local/lib/python3.10/dist-packages/django/db/backends/utils.py", line 75, in _execute_with_wrappers
    return executor(sql, params, many, context)
  File "/usr/local/lib/python3.10/dist-packages/django/db/backends/utils.py", line 79, in _execute
    with self.db.wrap_database_errors:
  File "/usr/local/lib/python3.10/dist-packages/django/db/utils.py", line 90, in __exit__
    raise dj_exc_value.with_traceback(traceback) from exc_value
  File "/usr/local/lib/python3.10/dist-packages/django/db/backends/utils.py", line 84, in _execute
    return self.cursor.execute(sql, params)
  File "/usr/local/lib/python3.10/dist-packages/django/db/backends/sqlite3/base.py", line 423, in execute
    return Database.Cursor.execute(self, query, params)
django.db.utils.IntegrityError: NOT NULL constraint failed: interviews_interview.interviewer_id
[18/Sep/2025 11:52:55] "POST /api/interviews/ HTTP/1.1" 500 222606
/home/james/abc/backend/interviews/models.py changed, reloading.
Watching for file changes with StatReloader
Performing system checks...

System check identified no issues (0 silenced).
September 18, 2025 - 11:57:37
Django version 3.2.16, using settings 'interview_system.settings'
Starting development server at http://0.0.0.0:8000/
Quit the server with CONTROL-C.
Watching for file changes with StatReloader
Performing system checks...

System check identified no issues (0 silenced).
September 18, 2025 - 11:59:17
Django version 3.2.16, using settings 'interview_system.settings'
Starting development server at http://0.0.0.0:8000/
Quit the server with CONTROL-C.
[18/Sep/2025 11:59:25] "GET /admin/interviews/interview/ HTTP/1.1" 200 15118
[18/Sep/2025 11:59:25] "GET /admin/jsi18n/ HTTP/1.1" 200 8398
[18/Sep/2025 12:00:25] "POST /api/interviews/ HTTP/1.1" 201 265
[18/Sep/2025 12:00:25] "GET /api/dashboard/stats/ HTTP/1.1" 200 282
[18/Sep/2025 12:00:25] "GET /api/interviews/ HTTP/1.1" 200 5068
[18/Sep/2025 12:00:33] "OPTIONS /api/interviews/6/complete_interview/ HTTP/1.1" 200 0
Bad Request: /api/interviews/6/complete_interview/
[18/Sep/2025 12:00:34] "POST /api/interviews/6/complete_interview/ HTTP/1.1" 400 45
[18/Sep/2025 12:04:34] "GET /api/dashboard/stats/ HTTP/1.1" 200 282
[18/Sep/2025 12:04:34] "GET /api/interviews/ HTTP/1.1" 200 5068
Method Not Allowed: /api/interviews/4/complete_interview/
[18/Sep/2025 12:05:11] "GET /api/interviews/4/complete_interview/ HTTP/1.1" 405 20279
[18/Sep/2025 12:51:02] "GET /admin/interviews/interview/ HTTP/1.1" 200 15819
[18/Sep/2025 12:51:02] "GET /static/admin/css/base.css HTTP/1.1" 304 0
[18/Sep/2025 12:51:02] "GET /static/admin/css/nav_sidebar.css HTTP/1.1" 304 0
[18/Sep/2025 12:51:02] "GET /static/admin/css/changelists.css HTTP/1.1" 304 0
[18/Sep/2025 12:51:02] "GET /static/admin/css/responsive.css HTTP/1.1" 304 0
[18/Sep/2025 12:51:02] "GET /static/admin/js/jquery.init.js HTTP/1.1" 304 0
[18/Sep/2025 12:51:02] "GET /admin/jsi18n/ HTTP/1.1" 200 8398
[18/Sep/2025 12:51:02] "GET /static/admin/js/vendor/jquery/jquery.js HTTP/1.1" 304 0
[18/Sep/2025 12:51:02] "GET /static/admin/js/admin/RelatedObjectLookups.js HTTP/1.1" 304 0
[18/Sep/2025 12:51:02] "GET /static/admin/js/core.js HTTP/1.1" 304 0
[18/Sep/2025 12:51:02] "GET /static/admin/css/fonts.css HTTP/1.1" 304 0
[18/Sep/2025 12:51:02] "GET /static/admin/js/urlify.js HTTP/1.1" 304 0
[18/Sep/2025 12:51:02] "GET /static/admin/js/actions.js HTTP/1.1" 304 0
[18/Sep/2025 12:51:03] "GET /static/admin/js/prepopulate.js HTTP/1.1" 304 0
[18/Sep/2025 12:51:03] "GET /static/admin/js/vendor/xregexp/xregexp.js HTTP/1.1" 304 0
[18/Sep/2025 12:51:03] "GET /static/admin/img/search.svg HTTP/1.1" 304 0
[18/Sep/2025 12:51:03] "GET /static/admin/img/icon-no.svg HTTP/1.1" 304 0
[18/Sep/2025 12:51:03] "GET /static/admin/js/nav_sidebar.js HTTP/1.1" 304 0
[18/Sep/2025 12:51:03] "GET /static/admin/img/tooltag-add.svg HTTP/1.1" 304 0
[18/Sep/2025 12:51:03] "GET /static/admin/img/icon-addlink.svg HTTP/1.1" 304 0
[18/Sep/2025 12:51:03] "GET /static/admin/img/sorting-icons.svg HTTP/1.1" 304 0
[18/Sep/2025 12:51:03] "GET /static/admin/fonts/Roboto-Light-webfont.woff HTTP/1.1" 304 0
[18/Sep/2025 12:51:03] "GET /static/admin/fonts/Roboto-Regular-webfont.woff HTTP/1.1" 304 0
[18/Sep/2025 12:51:03] "GET /static/admin/fonts/Roboto-Bold-webfont.woff HTTP/1.1" 304 0
[18/Sep/2025 12:51:07] "GET /admin/interviews/ HTTP/1.1" 200 3699
[18/Sep/2025 12:51:07] "GET /static/admin/css/dashboard.css HTTP/1.1" 304 0
[18/Sep/2025 12:51:07] "GET /static/admin/img/icon-changelink.svg HTTP/1.1" 304 0
[18/Sep/2025 12:51:09] "GET /admin/ HTTP/1.1" 200 4875
[18/Sep/2025 12:54:08] "GET /api/dashboard/stats/ HTTP/1.1" 200 282
[18/Sep/2025 12:54:08] "GET /api/interviews/ HTTP/1.1" 200 5068
[18/Sep/2025 12:54:19] "OPTIONS /api/companies/ HTTP/1.1" 200 0
[18/Sep/2025 12:54:19] "OPTIONS /api/positions/ HTTP/1.1" 200 0
[18/Sep/2025 12:54:19] "GET /api/companies/ HTTP/1.1" 200 365
[18/Sep/2025 12:54:19] "GET /api/positions/ HTTP/1.1" 200 1079
[18/Sep/2025 12:54:53] "OPTIONS /api/interviews/ HTTP/1.1" 200 0
[18/Sep/2025 12:54:53] "POST /api/interviews/ HTTP/1.1" 201 264
[18/Sep/2025 12:54:54] "OPTIONS /api/dashboard/stats/ HTTP/1.1" 200 0
[18/Sep/2025 12:54:54] "GET /api/interviews/ HTTP/1.1" 200 5797
[18/Sep/2025 12:54:54] "GET /api/dashboard/stats/ HTTP/1.1" 200 282
[18/Sep/2025 12:55:19] "GET /api/interviews/ HTTP/1.1" 200 5797
[18/Sep/2025 12:55:19] "GET /api/dashboard/stats/ HTTP/1.1" 200 282
Bad Request: /api/interviews/6/complete_interview/
[18/Sep/2025 12:55:26] "POST /api/interviews/6/complete_interview/ HTTP/1.1" 400 45
[18/Sep/2025 12:56:01] "GET /api/companies/ HTTP/1.1" 200 365
[18/Sep/2025 12:56:01] "GET /api/positions/ HTTP/1.1" 200 1079
[18/Sep/2025 12:58:33] "GET /api/companies/ HTTP/1.1" 200 365
[18/Sep/2025 12:58:33] "GET /api/positions/ HTTP/1.1" 200 1079
[18/Sep/2025 13:02:14] "OPTIONS /api/dashboard/stats/ HTTP/1.1" 200 0
[18/Sep/2025 13:02:14] "OPTIONS /api/interviews/ HTTP/1.1" 200 0
[18/Sep/2025 13:02:14] "GET /api/dashboard/stats/ HTTP/1.1" 200 282
[18/Sep/2025 13:02:14] "GET /api/interviews/ HTTP/1.1" 200 5797
Bad Request: /api/interviews/
[18/Sep/2025 13:02:47] "POST /api/interviews/ HTTP/1.1" 400 127
Bad Request: /api/interviews/
[18/Sep/2025 13:03:00] "POST /api/interviews/ HTTP/1.1" 400 80
Bad Request: /api/interviews/
[18/Sep/2025 13:03:04] "POST /api/interviews/ HTTP/1.1" 400 80
/home/james/abc/backend/interviews/serializers.py changed, reloading.
Watching for file changes with StatReloader
Performing system checks...

System check identified no issues (0 silenced).
September 18, 2025 - 13:06:14
Django version 3.2.16, using settings 'interview_system.settings'
Starting development server at http://0.0.0.0:8000/
Quit the server with CONTROL-C.
/home/james/abc/backend/interviews/models.py changed, reloading.
Watching for file changes with StatReloader
Performing system checks...

System check identified no issues (0 silenced).
September 18, 2025 - 13:08:45
Django version 3.2.16, using settings 'interview_system.settings'
Starting development server at http://0.0.0.0:8000/
Quit the server with CONTROL-C.
Watching for file changes with StatReloader
Performing system checks...

System check identified no issues (0 silenced).
September 18, 2025 - 13:08:56
Django version 3.2.16, using settings 'interview_system.settings'
Starting development server at http://0.0.0.0:8000/
Quit the server with CONTROL-C.
[18/Sep/2025 13:09:08] "GET /admin/ HTTP/1.1" 200 4875
[18/Sep/2025 13:09:10] "GET /admin/interviews/company/ HTTP/1.1" 200 8802
[18/Sep/2025 13:09:10] "GET /admin/jsi18n/ HTTP/1.1" 200 8398
[18/Sep/2025 13:09:13] "GET /admin/interviews/jobposition/ HTTP/1.1" 200 10020
[18/Sep/2025 13:09:13] "GET /admin/jsi18n/ HTTP/1.1" 200 8398
Internal Server Error: /admin/interviews/interview/
Traceback (most recent call last):
  File "/usr/local/lib/python3.10/dist-packages/django/db/backends/utils.py", line 84, in _execute
    return self.cursor.execute(sql, params)
  File "/usr/local/lib/python3.10/dist-packages/django/db/backends/sqlite3/base.py", line 423, in execute
    return Database.Cursor.execute(self, query, params)
sqlite3.OperationalError: no such column: interviews_interview.company_name

The above exception was the direct cause of the following exception:

Traceback (most recent call last):
  File "/usr/local/lib/python3.10/dist-packages/django/core/handlers/exception.py", line 47, in inner
    response = get_response(request)
  File "/usr/local/lib/python3.10/dist-packages/django/core/handlers/base.py", line 181, in _get_response
    response = wrapped_callback(request, *callback_args, **callback_kwargs)
  File "/usr/local/lib/python3.10/dist-packages/django/contrib/admin/options.py", line 616, in wrapper
    return self.admin_site.admin_view(view)(*args, **kwargs)
  File "/usr/local/lib/python3.10/dist-packages/django/utils/decorators.py", line 130, in _wrapped_view
    response = view_func(request, *args, **kwargs)
  File "/usr/local/lib/python3.10/dist-packages/django/views/decorators/cache.py", line 44, in _wrapped_view_func
    response = view_func(request, *args, **kwargs)
  File "/usr/local/lib/python3.10/dist-packages/django/contrib/admin/sites.py", line 232, in inner
    return view(request, *args, **kwargs)
  File "/usr/local/lib/python3.10/dist-packages/django/utils/decorators.py", line 43, in _wrapper
    return bound_method(*args, **kwargs)
  File "/usr/local/lib/python3.10/dist-packages/django/utils/decorators.py", line 130, in _wrapped_view
    response = view_func(request, *args, **kwargs)
  File "/usr/local/lib/python3.10/dist-packages/django/contrib/admin/options.py", line 1815, in changelist_view
    'selection_note': _('0 of %(cnt)s selected') % {'cnt': len(cl.result_list)},
  File "/usr/local/lib/python3.10/dist-packages/django/db/models/query.py", line 262, in __len__
    self._fetch_all()
  File "/usr/local/lib/python3.10/dist-packages/django/db/models/query.py", line 1324, in _fetch_all
    self._result_cache = list(self._iterable_class(self))
  File "/usr/local/lib/python3.10/dist-packages/django/db/models/query.py", line 51, in __iter__
    results = compiler.execute_sql(chunked_fetch=self.chunked_fetch, chunk_size=self.chunk_size)
  File "/usr/local/lib/python3.10/dist-packages/django/db/models/sql/compiler.py", line 1175, in execute_sql
    cursor.execute(sql, params)
  File "/usr/local/lib/python3.10/dist-packages/django/db/backends/utils.py", line 98, in execute
    return super().execute(sql, params)
  File "/usr/local/lib/python3.10/dist-packages/django/db/backends/utils.py", line 66, in execute
    return self._execute_with_wrappers(sql, params, many=False, executor=self._execute)
  File "/usr/local/lib/python3.10/dist-packages/django/db/backends/utils.py", line 75, in _execute_with_wrappers
    return executor(sql, params, many, context)
  File "/usr/local/lib/python3.10/dist-packages/django/db/backends/utils.py", line 79, in _execute
    with self.db.wrap_database_errors:
  File "/usr/local/lib/python3.10/dist-packages/django/db/utils.py", line 90, in __exit__
    raise dj_exc_value.with_traceback(traceback) from exc_value
  File "/usr/local/lib/python3.10/dist-packages/django/db/backends/utils.py", line 84, in _execute
    return self.cursor.execute(sql, params)
  File "/usr/local/lib/python3.10/dist-packages/django/db/backends/sqlite3/base.py", line 423, in execute
    return Database.Cursor.execute(self, query, params)
django.db.utils.OperationalError: no such column: interviews_interview.company_name
[18/Sep/2025 13:09:15] "GET /admin/interviews/interview/ HTTP/1.1" 500 166754
[18/Sep/2025 13:09:19] "GET /admin/interviews/jobposition/ HTTP/1.1" 200 10020
Watching for file changes with StatReloader
Performing system checks...

System check identified no issues (0 silenced).
September 18, 2025 - 13:10:01
Django version 3.2.16, using settings 'interview_system.settings'
Starting development server at http://0.0.0.0:8000/
Quit the server with CONTROL-C.
[18/Sep/2025 13:10:07] "GET /admin/interviews/jobposition/ HTTP/1.1" 200 10020
[18/Sep/2025 13:10:07] "GET /admin/jsi18n/ HTTP/1.1" 200 8398
Internal Server Error: /admin/interviews/interview/
Traceback (most recent call last):
  File "/usr/local/lib/python3.10/dist-packages/django/db/backends/utils.py", line 84, in _execute
    return self.cursor.execute(sql, params)
  File "/usr/local/lib/python3.10/dist-packages/django/db/backends/sqlite3/base.py", line 423, in execute
    return Database.Cursor.execute(self, query, params)
sqlite3.OperationalError: no such column: interviews_interview.company_name

The above exception was the direct cause of the following exception:

Traceback (most recent call last):
  File "/usr/local/lib/python3.10/dist-packages/django/core/handlers/exception.py", line 47, in inner
    response = get_response(request)
  File "/usr/local/lib/python3.10/dist-packages/django/core/handlers/base.py", line 181, in _get_response
    response = wrapped_callback(request, *callback_args, **callback_kwargs)
  File "/usr/local/lib/python3.10/dist-packages/django/contrib/admin/options.py", line 616, in wrapper
    return self.admin_site.admin_view(view)(*args, **kwargs)
  File "/usr/local/lib/python3.10/dist-packages/django/utils/decorators.py", line 130, in _wrapped_view
    response = view_func(request, *args, **kwargs)
  File "/usr/local/lib/python3.10/dist-packages/django/views/decorators/cache.py", line 44, in _wrapped_view_func
    response = view_func(request, *args, **kwargs)
  File "/usr/local/lib/python3.10/dist-packages/django/contrib/admin/sites.py", line 232, in inner
    return view(request, *args, **kwargs)
  File "/usr/local/lib/python3.10/dist-packages/django/utils/decorators.py", line 43, in _wrapper
    return bound_method(*args, **kwargs)
  File "/usr/local/lib/python3.10/dist-packages/django/utils/decorators.py", line 130, in _wrapped_view
    response = view_func(request, *args, **kwargs)
  File "/usr/local/lib/python3.10/dist-packages/django/contrib/admin/options.py", line 1815, in changelist_view
    'selection_note': _('0 of %(cnt)s selected') % {'cnt': len(cl.result_list)},
  File "/usr/local/lib/python3.10/dist-packages/django/db/models/query.py", line 262, in __len__
    self._fetch_all()
  File "/usr/local/lib/python3.10/dist-packages/django/db/models/query.py", line 1324, in _fetch_all
    self._result_cache = list(self._iterable_class(self))
  File "/usr/local/lib/python3.10/dist-packages/django/db/models/query.py", line 51, in __iter__
    results = compiler.execute_sql(chunked_fetch=self.chunked_fetch, chunk_size=self.chunk_size)
  File "/usr/local/lib/python3.10/dist-packages/django/db/models/sql/compiler.py", line 1175, in execute_sql
    cursor.execute(sql, params)
  File "/usr/local/lib/python3.10/dist-packages/django/db/backends/utils.py", line 98, in execute
    return super().execute(sql, params)
  File "/usr/local/lib/python3.10/dist-packages/django/db/backends/utils.py", line 66, in execute
    return self._execute_with_wrappers(sql, params, many=False, executor=self._execute)
  File "/usr/local/lib/python3.10/dist-packages/django/db/backends/utils.py", line 75, in _execute_with_wrappers
    return executor(sql, params, many, context)
  File "/usr/local/lib/python3.10/dist-packages/django/db/backends/utils.py", line 79, in _execute
    with self.db.wrap_database_errors:
  File "/usr/local/lib/python3.10/dist-packages/django/db/utils.py", line 90, in __exit__
    raise dj_exc_value.with_traceback(traceback) from exc_value
  File "/usr/local/lib/python3.10/dist-packages/django/db/backends/utils.py", line 84, in _execute
    return self.cursor.execute(sql, params)
  File "/usr/local/lib/python3.10/dist-packages/django/db/backends/sqlite3/base.py", line 423, in execute
    return Database.Cursor.execute(self, query, params)
django.db.utils.OperationalError: no such column: interviews_interview.company_name
[18/Sep/2025 13:10:09] "GET /admin/interviews/interview/ HTTP/1.1" 500 166754
[18/Sep/2025 13:10:21] "GET /api/dashboard/stats/ HTTP/1.1" 200 282
Internal Server Error: /api/interviews/
Traceback (most recent call last):
  File "/usr/local/lib/python3.10/dist-packages/django/db/backends/utils.py", line 84, in _execute
    return self.cursor.execute(sql, params)
  File "/usr/local/lib/python3.10/dist-packages/django/db/backends/sqlite3/base.py", line 423, in execute
    return Database.Cursor.execute(self, query, params)
sqlite3.OperationalError: no such column: interviews_interview.company_name

The above exception was the direct cause of the following exception:

Traceback (most recent call last):
  File "/usr/local/lib/python3.10/dist-packages/django/core/handlers/exception.py", line 47, in inner
    response = get_response(request)
  File "/usr/local/lib/python3.10/dist-packages/django/core/handlers/base.py", line 181, in _get_response
    response = wrapped_callback(request, *callback_args, **callback_kwargs)
  File "/usr/local/lib/python3.10/dist-packages/django/views/decorators/csrf.py", line 54, in wrapped_view
    return view_func(*args, **kwargs)
  File "/usr/local/lib/python3.10/dist-packages/rest_framework/viewsets.py", line 125, in view
    return self.dispatch(request, *args, **kwargs)
  File "/usr/local/lib/python3.10/dist-packages/rest_framework/views.py", line 509, in dispatch
    response = self.handle_exception(exc)
  File "/usr/local/lib/python3.10/dist-packages/rest_framework/views.py", line 469, in handle_exception
    self.raise_uncaught_exception(exc)
  File "/usr/local/lib/python3.10/dist-packages/rest_framework/views.py", line 480, in raise_uncaught_exception
    raise exc
  File "/usr/local/lib/python3.10/dist-packages/rest_framework/views.py", line 506, in dispatch
    response = handler(request, *args, **kwargs)
  File "/usr/local/lib/python3.10/dist-packages/rest_framework/mixins.py", line 46, in list
    return Response(serializer.data)
  File "/usr/local/lib/python3.10/dist-packages/rest_framework/serializers.py", line 768, in data
    ret = super().data
  File "/usr/local/lib/python3.10/dist-packages/rest_framework/serializers.py", line 253, in data
    self._data = self.to_representation(self.instance)
  File "/usr/local/lib/python3.10/dist-packages/rest_framework/serializers.py", line 686, in to_representation
    return [
  File "/usr/local/lib/python3.10/dist-packages/django/db/models/query.py", line 280, in __iter__
    self._fetch_all()
  File "/usr/local/lib/python3.10/dist-packages/django/db/models/query.py", line 1324, in _fetch_all
    self._result_cache = list(self._iterable_class(self))
  File "/usr/local/lib/python3.10/dist-packages/django/db/models/query.py", line 51, in __iter__
    results = compiler.execute_sql(chunked_fetch=self.chunked_fetch, chunk_size=self.chunk_size)
  File "/usr/local/lib/python3.10/dist-packages/django/db/models/sql/compiler.py", line 1175, in execute_sql
    cursor.execute(sql, params)
  File "/usr/local/lib/python3.10/dist-packages/django/db/backends/utils.py", line 98, in execute
    return super().execute(sql, params)
  File "/usr/local/lib/python3.10/dist-packages/django/db/backends/utils.py", line 66, in execute
    return self._execute_with_wrappers(sql, params, many=False, executor=self._execute)
  File "/usr/local/lib/python3.10/dist-packages/django/db/backends/utils.py", line 75, in _execute_with_wrappers
    return executor(sql, params, many, context)
  File "/usr/local/lib/python3.10/dist-packages/django/db/backends/utils.py", line 79, in _execute
    with self.db.wrap_database_errors:
  File "/usr/local/lib/python3.10/dist-packages/django/db/utils.py", line 90, in __exit__
    raise dj_exc_value.with_traceback(traceback) from exc_value
  File "/usr/local/lib/python3.10/dist-packages/django/db/backends/utils.py", line 84, in _execute
    return self.cursor.execute(sql, params)
  File "/usr/local/lib/python3.10/dist-packages/django/db/backends/sqlite3/base.py", line 423, in execute
    return Database.Cursor.execute(self, query, params)
django.db.utils.OperationalError: no such column: interviews_interview.company_name
[18/Sep/2025 13:10:21] "GET /api/interviews/ HTTP/1.1" 500 175356
Watching for file changes with StatReloader
Performing system checks...

System check identified no issues (0 silenced).
September 18, 2025 - 13:12:12
Django version 3.2.16, using settings 'interview_system.settings'
Starting development server at http://0.0.0.0:8000/
Quit the server with CONTROL-C.
Internal Server Error: /admin/interviews/interview/
Traceback (most recent call last):
  File "/usr/local/lib/python3.10/dist-packages/django/db/backends/utils.py", line 84, in _execute
    return self.cursor.execute(sql, params)
  File "/usr/local/lib/python3.10/dist-packages/django/db/backends/sqlite3/base.py", line 423, in execute
    return Database.Cursor.execute(self, query, params)
sqlite3.OperationalError: no such column: interviews_interview.company_name

The above exception was the direct cause of the following exception:

Traceback (most recent call last):
  File "/usr/local/lib/python3.10/dist-packages/django/core/handlers/exception.py", line 47, in inner
    response = get_response(request)
  File "/usr/local/lib/python3.10/dist-packages/django/core/handlers/base.py", line 181, in _get_response
    response = wrapped_callback(request, *callback_args, **callback_kwargs)
  File "/usr/local/lib/python3.10/dist-packages/django/contrib/admin/options.py", line 616, in wrapper
    return self.admin_site.admin_view(view)(*args, **kwargs)
  File "/usr/local/lib/python3.10/dist-packages/django/utils/decorators.py", line 130, in _wrapped_view
    response = view_func(request, *args, **kwargs)
  File "/usr/local/lib/python3.10/dist-packages/django/views/decorators/cache.py", line 44, in _wrapped_view_func
    response = view_func(request, *args, **kwargs)
  File "/usr/local/lib/python3.10/dist-packages/django/contrib/admin/sites.py", line 232, in inner
    return view(request, *args, **kwargs)
  File "/usr/local/lib/python3.10/dist-packages/django/utils/decorators.py", line 43, in _wrapper
    return bound_method(*args, **kwargs)
  File "/usr/local/lib/python3.10/dist-packages/django/utils/decorators.py", line 130, in _wrapped_view
    response = view_func(request, *args, **kwargs)
  File "/usr/local/lib/python3.10/dist-packages/django/contrib/admin/options.py", line 1815, in changelist_view
    'selection_note': _('0 of %(cnt)s selected') % {'cnt': len(cl.result_list)},
  File "/usr/local/lib/python3.10/dist-packages/django/db/models/query.py", line 262, in __len__
    self._fetch_all()
  File "/usr/local/lib/python3.10/dist-packages/django/db/models/query.py", line 1324, in _fetch_all
    self._result_cache = list(self._iterable_class(self))
  File "/usr/local/lib/python3.10/dist-packages/django/db/models/query.py", line 51, in __iter__
    results = compiler.execute_sql(chunked_fetch=self.chunked_fetch, chunk_size=self.chunk_size)
  File "/usr/local/lib/python3.10/dist-packages/django/db/models/sql/compiler.py", line 1175, in execute_sql
    cursor.execute(sql, params)
  File "/usr/local/lib/python3.10/dist-packages/django/db/backends/utils.py", line 98, in execute
    return super().execute(sql, params)
  File "/usr/local/lib/python3.10/dist-packages/django/db/backends/utils.py", line 66, in execute
    return self._execute_with_wrappers(sql, params, many=False, executor=self._execute)
  File "/usr/local/lib/python3.10/dist-packages/django/db/backends/utils.py", line 75, in _execute_with_wrappers
    return executor(sql, params, many, context)
  File "/usr/local/lib/python3.10/dist-packages/django/db/backends/utils.py", line 79, in _execute
    with self.db.wrap_database_errors:
  File "/usr/local/lib/python3.10/dist-packages/django/db/utils.py", line 90, in __exit__
    raise dj_exc_value.with_traceback(traceback) from exc_value
  File "/usr/local/lib/python3.10/dist-packages/django/db/backends/utils.py", line 84, in _execute
    return self.cursor.execute(sql, params)
  File "/usr/local/lib/python3.10/dist-packages/django/db/backends/sqlite3/base.py", line 423, in execute
    return Database.Cursor.execute(self, query, params)
django.db.utils.OperationalError: no such column: interviews_interview.company_name
[18/Sep/2025 13:12:17] "GET /admin/interviews/interview/ HTTP/1.1" 500 166715
[18/Sep/2025 13:12:19] "GET /admin/interviews/jobposition/ HTTP/1.1" 200 10020
[18/Sep/2025 13:12:21] "GET /admin/interviews/jobposition/ HTTP/1.1" 200 10020
[18/Sep/2025 13:12:21] "GET /admin/jsi18n/ HTTP/1.1" 200 8398
[18/Sep/2025 13:12:23] "GET /admin/auth/user/ HTTP/1.1" 200 10285
[18/Sep/2025 13:12:23] "GET /static/admin/img/icon-yes.svg HTTP/1.1" 304 0
[18/Sep/2025 13:12:23] "GET /admin/jsi18n/ HTTP/1.1" 200 8398
[18/Sep/2025 13:12:24] "GET /admin/auth/group/ HTTP/1.1" 200 5877
[18/Sep/2025 13:12:25] "GET /admin/jsi18n/ HTTP/1.1" 200 8398
[18/Sep/2025 13:12:25] "GET /admin/interviews/company/ HTTP/1.1" 200 8802
[18/Sep/2025 13:12:26] "GET /admin/jsi18n/ HTTP/1.1" 200 8398
[18/Sep/2025 13:12:26] "GET /admin/interviews/jobposition/ HTTP/1.1" 200 10020
[18/Sep/2025 13:12:27] "GET /admin/jsi18n/ HTTP/1.1" 200 8398
Internal Server Error: /admin/interviews/interview/
Traceback (most recent call last):
  File "/usr/local/lib/python3.10/dist-packages/django/db/backends/utils.py", line 84, in _execute
    return self.cursor.execute(sql, params)
  File "/usr/local/lib/python3.10/dist-packages/django/db/backends/sqlite3/base.py", line 423, in execute
    return Database.Cursor.execute(self, query, params)
sqlite3.OperationalError: no such column: interviews_interview.company_name

The above exception was the direct cause of the following exception:

Traceback (most recent call last):
  File "/usr/local/lib/python3.10/dist-packages/django/core/handlers/exception.py", line 47, in inner
    response = get_response(request)
  File "/usr/local/lib/python3.10/dist-packages/django/core/handlers/base.py", line 181, in _get_response
    response = wrapped_callback(request, *callback_args, **callback_kwargs)
  File "/usr/local/lib/python3.10/dist-packages/django/contrib/admin/options.py", line 616, in wrapper
    return self.admin_site.admin_view(view)(*args, **kwargs)
  File "/usr/local/lib/python3.10/dist-packages/django/utils/decorators.py", line 130, in _wrapped_view
    response = view_func(request, *args, **kwargs)
  File "/usr/local/lib/python3.10/dist-packages/django/views/decorators/cache.py", line 44, in _wrapped_view_func
    response = view_func(request, *args, **kwargs)
  File "/usr/local/lib/python3.10/dist-packages/django/contrib/admin/sites.py", line 232, in inner
    return view(request, *args, **kwargs)
  File "/usr/local/lib/python3.10/dist-packages/django/utils/decorators.py", line 43, in _wrapper
    return bound_method(*args, **kwargs)
  File "/usr/local/lib/python3.10/dist-packages/django/utils/decorators.py", line 130, in _wrapped_view
    response = view_func(request, *args, **kwargs)
  File "/usr/local/lib/python3.10/dist-packages/django/contrib/admin/options.py", line 1815, in changelist_view
    'selection_note': _('0 of %(cnt)s selected') % {'cnt': len(cl.result_list)},
  File "/usr/local/lib/python3.10/dist-packages/django/db/models/query.py", line 262, in __len__
    self._fetch_all()
  File "/usr/local/lib/python3.10/dist-packages/django/db/models/query.py", line 1324, in _fetch_all
    self._result_cache = list(self._iterable_class(self))
  File "/usr/local/lib/python3.10/dist-packages/django/db/models/query.py", line 51, in __iter__
    results = compiler.execute_sql(chunked_fetch=self.chunked_fetch, chunk_size=self.chunk_size)
  File "/usr/local/lib/python3.10/dist-packages/django/db/models/sql/compiler.py", line 1175, in execute_sql
    cursor.execute(sql, params)
  File "/usr/local/lib/python3.10/dist-packages/django/db/backends/utils.py", line 98, in execute
    return super().execute(sql, params)
  File "/usr/local/lib/python3.10/dist-packages/django/db/backends/utils.py", line 66, in execute
    return self._execute_with_wrappers(sql, params, many=False, executor=self._execute)
  File "/usr/local/lib/python3.10/dist-packages/django/db/backends/utils.py", line 75, in _execute_with_wrappers
    return executor(sql, params, many, context)
  File "/usr/local/lib/python3.10/dist-packages/django/db/backends/utils.py", line 79, in _execute
    with self.db.wrap_database_errors:
  File "/usr/local/lib/python3.10/dist-packages/django/db/utils.py", line 90, in __exit__
    raise dj_exc_value.with_traceback(traceback) from exc_value
  File "/usr/local/lib/python3.10/dist-packages/django/db/backends/utils.py", line 84, in _execute
    return self.cursor.execute(sql, params)
  File "/usr/local/lib/python3.10/dist-packages/django/db/backends/sqlite3/base.py", line 423, in execute
    return Database.Cursor.execute(self, query, params)
django.db.utils.OperationalError: no such column: interviews_interview.company_name
[18/Sep/2025 13:12:28] "GET /admin/interviews/interview/ HTTP/1.1" 500 166754
Watching for file changes with StatReloader
Performing system checks...

System check identified no issues (0 silenced).
September 18, 2025 - 13:14:31
Django version 3.2.16, using settings 'interview_system.settings'
Starting development server at http://0.0.0.0:8000/
Quit the server with CONTROL-C.
Not Found: /
[18/Sep/2025 13:14:31] "GET / HTTP/1.1" 404 2411
[18/Sep/2025 13:14:42] "GET /admin/ HTTP/1.1" 302 0
[18/Sep/2025 13:14:42] "GET /admin/login/?next=/admin/ HTTP/1.1" 200 2216
[18/Sep/2025 13:14:42] "GET /static/admin/css/login.css HTTP/1.1" 200 939
[18/Sep/2025 13:14:42] "GET /static/admin/css/base.css HTTP/1.1" 200 19513
[18/Sep/2025 13:14:42] "GET /static/admin/css/nav_sidebar.css HTTP/1.1" 200 2271
[18/Sep/2025 13:14:42] "GET /static/admin/js/nav_sidebar.js HTTP/1.1" 200 1360
[18/Sep/2025 13:14:42] "GET /static/admin/css/responsive.css HTTP/1.1" 200 18545
[18/Sep/2025 13:14:42] "GET /static/admin/css/fonts.css HTTP/1.1" 200 423
[18/Sep/2025 13:14:42] "GET /static/admin/fonts/Roboto-Regular-webfont.woff HTTP/1.1" 200 85876
[18/Sep/2025 13:14:42] "GET /static/admin/fonts/Roboto-Light-webfont.woff HTTP/1.1" 200 85692
[18/Sep/2025 13:14:46] "POST /admin/login/?next=/admin/ HTTP/1.1" 200 2348
[18/Sep/2025 13:14:46] "GET /static/admin/fonts/Roboto-Bold-webfont.woff HTTP/1.1" 200 86184
[18/Sep/2025 13:14:56] "POST /admin/login/?next=/admin/ HTTP/1.1" 302 0
[18/Sep/2025 13:14:56] "GET /admin/ HTTP/1.1" 200 4875
[18/Sep/2025 13:14:56] "GET /static/admin/css/dashboard.css HTTP/1.1" 200 380
[18/Sep/2025 13:14:56] "GET /static/admin/img/icon-addlink.svg HTTP/1.1" 200 331
[18/Sep/2025 13:14:56] "GET /static/admin/img/icon-changelink.svg HTTP/1.1" 200 380
[18/Sep/2025 13:14:58] "GET /admin/interviews/interview/ HTTP/1.1" 200 15185
[18/Sep/2025 13:14:58] "GET /static/admin/css/changelists.css HTTP/1.1" 200 6874
[18/Sep/2025 13:14:58] "GET /static/admin/js/jquery.init.js HTTP/1.1" 200 347
[18/Sep/2025 13:14:58] "GET /static/admin/js/core.js HTTP/1.1" 200 5698
[18/Sep/2025 13:14:58] "GET /admin/jsi18n/ HTTP/1.1" 200 8398
[18/Sep/2025 13:14:58] "GET /static/admin/js/admin/RelatedObjectLookups.js HTTP/1.1" 200 5984
[18/Sep/2025 13:14:58] "GET /static/admin/js/actions.js HTTP/1.1" 200 7867
[18/Sep/2025 13:14:58] "GET /static/admin/js/urlify.js HTTP/1.1" 200 7902
[18/Sep/2025 13:14:58] "GET /static/admin/js/vendor/jquery/jquery.js HTTP/1.1" 200 287630
[18/Sep/2025 13:14:58] "GET /static/admin/js/prepopulate.js HTTP/1.1" 200 1531
[18/Sep/2025 13:14:58] "GET /static/admin/img/search.svg HTTP/1.1" 200 458
[18/Sep/2025 13:14:58] "GET /static/admin/img/icon-no.svg HTTP/1.1" 200 560
[18/Sep/2025 13:14:58] "GET /static/admin/js/vendor/xregexp/xregexp.js HTTP/1.1" 200 232381
[18/Sep/2025 13:14:58] "GET /static/admin/img/tooltag-add.svg HTTP/1.1" 200 331
[18/Sep/2025 13:14:58] "GET /static/admin/img/sorting-icons.svg HTTP/1.1" 200 1097
[18/Sep/2025 13:15:08] "GET /api/dashboard/stats/ HTTP/1.1" 200 249
[18/Sep/2025 13:15:08] "GET /api/interviews/ HTTP/1.1" 200 4338
Bad Request: /api/interviews/
[18/Sep/2025 13:15:40] "POST /api/interviews/ HTTP/1.1" 400 61
[18/Sep/2025 13:15:57] "POST /api/interviews/ HTTP/1.1" 201 240
[18/Sep/2025 13:15:57] "GET /api/dashboard/stats/ HTTP/1.1" 200 282
[18/Sep/2025 13:15:57] "GET /api/interviews/ HTTP/1.1" 200 4982
[18/Sep/2025 13:16:03] "GET /admin/interviews/interview/ HTTP/1.1" 200 15952
[18/Sep/2025 13:16:03] "GET /admin/jsi18n/ HTTP/1.1" 200 8398
[18/Sep/2025 13:16:25] "OPTIONS /api/interviews/6/complete_interview/ HTTP/1.1" 200 0
Bad Request: /api/interviews/6/complete_interview/
[18/Sep/2025 13:16:25] "POST /api/interviews/6/complete_interview/ HTTP/1.1" 400 45
[18/Sep/2025 13:17:00] "GET /api/dashboard/stats/ HTTP/1.1" 200 282
[18/Sep/2025 13:17:00] "GET /api/interviews/ HTTP/1.1" 200 4982
Watching for file changes with StatReloader
Performing system checks...

System check identified no issues (0 silenced).
September 19, 2025 - 08:49:33
Django version 3.2.16, using settings 'interview_system.settings'
Starting development server at http://0.0.0.0:8000/
Quit the server with CONTROL-C.
[19/Sep/2025 08:49:45] "GET /admin/ HTTP/1.1" 302 0
[19/Sep/2025 08:49:45] "GET /admin/login/?next=/admin/ HTTP/1.1" 200 2216
[19/Sep/2025 08:49:50] "POST /admin/login/?next=/admin/ HTTP/1.1" 302 0
[19/Sep/2025 08:49:50] "GET /admin/ HTTP/1.1" 200 4875
[19/Sep/2025 08:49:53] "GET /admin/ HTTP/1.1" 200 4875
[19/Sep/2025 08:50:06] "GET /api/dashboard/stats/ HTTP/1.1" 200 282
[19/Sep/2025 08:50:06] "GET /api/interviews/ HTTP/1.1" 200 4982
Bad Request: /api/interviews/
[19/Sep/2025 08:50:26] "POST /api/interviews/ HTTP/1.1" 400 48
Bad Request: /api/interviews/
[19/Sep/2025 08:50:37] "POST /api/interviews/ HTTP/1.1" 400 61
[19/Sep/2025 08:50:44] "POST /api/interviews/ HTTP/1.1" 201 228
[19/Sep/2025 08:50:44] "GET /api/dashboard/stats/ HTTP/1.1" 200 315
[19/Sep/2025 08:50:44] "GET /api/interviews/ HTTP/1.1" 200 5607
[19/Sep/2025 08:51:07] "OPTIONS /api/interviews/5/upload_recording/ HTTP/1.1" 200 0
Bad Request: /api/interviews/5/upload_recording/
[19/Sep/2025 08:51:07] "POST /api/interviews/5/upload_recording/ HTTP/1.1" 400 33
[19/Sep/2025 08:51:25] "GET /api/dashboard/stats/ HTTP/1.1" 200 315
[19/Sep/2025 08:51:25] "GET /api/interviews/ HTTP/1.1" 200 5607
/home/james/abc/interview-platform-new/backend/interviews/models.py changed, reloading.
Watching for file changes with StatReloader
Performing system checks...

System check identified no issues (0 silenced).
September 19, 2025 - 08:54:14
Django version 3.2.16, using settings 'interview_system.settings'
Starting development server at http://0.0.0.0:8000/
Quit the server with CONTROL-C.
/home/james/abc/interview-platform-new/backend/interviews/urls.py changed, reloading.
Watching for file changes with StatReloader
Performing system checks...

Exception in thread django-main-thread:
Traceback (most recent call last):
  File "/usr/lib/python3.10/threading.py", line 1016, in _bootstrap_inner
    self.run()
  File "/usr/lib/python3.10/threading.py", line 953, in run
    self._target(*self._args, **self._kwargs)
  File "/usr/local/lib/python3.10/dist-packages/django/utils/autoreload.py", line 64, in wrapper
    fn(*args, **kwargs)
  File "/usr/local/lib/python3.10/dist-packages/django/core/management/commands/runserver.py", line 118, in inner_run
    self.check(display_num_errors=True)
  File "/usr/local/lib/python3.10/dist-packages/django/core/management/base.py", line 419, in check
    all_issues = checks.run_checks(
  File "/usr/local/lib/python3.10/dist-packages/django/core/checks/registry.py", line 76, in run_checks
    new_errors = check(app_configs=app_configs, databases=databases)
  File "/usr/local/lib/python3.10/dist-packages/django/core/checks/urls.py", line 13, in check_url_config
    return check_resolver(resolver)
  File "/usr/local/lib/python3.10/dist-packages/django/core/checks/urls.py", line 23, in check_resolver
    return check_method()
  File "/usr/local/lib/python3.10/dist-packages/django/urls/resolvers.py", line 416, in check
    for pattern in self.url_patterns:
  File "/usr/local/lib/python3.10/dist-packages/django/utils/functional.py", line 48, in __get__
    res = instance.__dict__[self.name] = self.func(instance)
  File "/usr/local/lib/python3.10/dist-packages/django/urls/resolvers.py", line 602, in url_patterns
    patterns = getattr(self.urlconf_module, "urlpatterns", self.urlconf_module)
  File "/usr/local/lib/python3.10/dist-packages/django/utils/functional.py", line 48, in __get__
    res = instance.__dict__[self.name] = self.func(instance)
  File "/usr/local/lib/python3.10/dist-packages/django/urls/resolvers.py", line 595, in urlconf_module
    return import_module(self.urlconf_name)
  File "/usr/lib/python3.10/importlib/__init__.py", line 126, in import_module
    return _bootstrap._gcd_import(name[level:], package, level)
  File "<frozen importlib._bootstrap>", line 1050, in _gcd_import
  File "<frozen importlib._bootstrap>", line 1027, in _find_and_load
  File "<frozen importlib._bootstrap>", line 1006, in _find_and_load_unlocked
  File "<frozen importlib._bootstrap>", line 688, in _load_unlocked
  File "<frozen importlib._bootstrap_external>", line 883, in exec_module
  File "<frozen importlib._bootstrap>", line 241, in _call_with_frames_removed
  File "/home/james/abc/interview-platform-new/backend/interview_system/urls.py", line 8, in <module>
    path('api/', include('interviews.urls')),
  File "/usr/local/lib/python3.10/dist-packages/django/urls/conf.py", line 34, in include
    urlconf_module = import_module(urlconf_module)
  File "/usr/lib/python3.10/importlib/__init__.py", line 126, in import_module
    return _bootstrap._gcd_import(name[level:], package, level)
  File "<frozen importlib._bootstrap>", line 1050, in _gcd_import
  File "<frozen importlib._bootstrap>", line 1027, in _find_and_load
  File "<frozen importlib._bootstrap>", line 1006, in _find_and_load_unlocked
  File "<frozen importlib._bootstrap>", line 688, in _load_unlocked
  File "<frozen importlib._bootstrap_external>", line 883, in exec_module
  File "<frozen importlib._bootstrap>", line 241, in _call_with_frames_removed
  File "/home/james/abc/interview-platform-new/backend/interviews/urls.py", line 7, in <module>
    from .student_views import StudentInfoViewSet, EducationHistoryViewSet, CertificateViewSet
  File "/home/james/abc/interview-platform-new/backend/interviews/student_views.py", line 11, in <module>
    import pandas as pd
  File "/usr/local/lib/python3.10/dist-packages/pandas/__init__.py", line 22, in <module>
    from pandas.compat import is_numpy_dev as _is_numpy_dev  # pyright: ignore # noqa:F401
  File "/usr/local/lib/python3.10/dist-packages/pandas/compat/__init__.py", line 18, in <module>
    from pandas.compat.numpy import (
  File "/usr/local/lib/python3.10/dist-packages/pandas/compat/numpy/__init__.py", line 4, in <module>
    from pandas.util.version import Version
  File "/usr/local/lib/python3.10/dist-packages/pandas/util/__init__.py", line 2, in <module>
    from pandas.util._decorators import (  # noqa:F401
  File "/usr/local/lib/python3.10/dist-packages/pandas/util/_decorators.py", line 14, in <module>
    from pandas._libs.properties import cache_readonly
  File "/usr/local/lib/python3.10/dist-packages/pandas/_libs/__init__.py", line 13, in <module>
    from pandas._libs.interval import Interval
  File "pandas/_libs/interval.pyx", line 1, in init pandas._libs.interval
ValueError: numpy.dtype size changed, may indicate binary incompatibility. Expected 96 from C header, got 88 from PyObject
/home/james/abc/interview-platform-new/backend/interviews/admin.py changed, reloading.
Watching for file changes with StatReloader
Performing system checks...

Exception in thread django-main-thread:
Traceback (most recent call last):
  File "/usr/lib/python3.10/threading.py", line 1016, in _bootstrap_inner
    self.run()
  File "/usr/lib/python3.10/threading.py", line 953, in run
    self._target(*self._args, **self._kwargs)
  File "/usr/local/lib/python3.10/dist-packages/django/utils/autoreload.py", line 64, in wrapper
    fn(*args, **kwargs)
  File "/usr/local/lib/python3.10/dist-packages/django/core/management/commands/runserver.py", line 118, in inner_run
    self.check(display_num_errors=True)
  File "/usr/local/lib/python3.10/dist-packages/django/core/management/base.py", line 419, in check
    all_issues = checks.run_checks(
  File "/usr/local/lib/python3.10/dist-packages/django/core/checks/registry.py", line 76, in run_checks
    new_errors = check(app_configs=app_configs, databases=databases)
  File "/usr/local/lib/python3.10/dist-packages/django/core/checks/urls.py", line 13, in check_url_config
    return check_resolver(resolver)
  File "/usr/local/lib/python3.10/dist-packages/django/core/checks/urls.py", line 23, in check_resolver
    return check_method()
  File "/usr/local/lib/python3.10/dist-packages/django/urls/resolvers.py", line 416, in check
    for pattern in self.url_patterns:
  File "/usr/local/lib/python3.10/dist-packages/django/utils/functional.py", line 48, in __get__
    res = instance.__dict__[self.name] = self.func(instance)
  File "/usr/local/lib/python3.10/dist-packages/django/urls/resolvers.py", line 602, in url_patterns
    patterns = getattr(self.urlconf_module, "urlpatterns", self.urlconf_module)
  File "/usr/local/lib/python3.10/dist-packages/django/utils/functional.py", line 48, in __get__
    res = instance.__dict__[self.name] = self.func(instance)
  File "/usr/local/lib/python3.10/dist-packages/django/urls/resolvers.py", line 595, in urlconf_module
    return import_module(self.urlconf_name)
  File "/usr/lib/python3.10/importlib/__init__.py", line 126, in import_module
    return _bootstrap._gcd_import(name[level:], package, level)
  File "<frozen importlib._bootstrap>", line 1050, in _gcd_import
  File "<frozen importlib._bootstrap>", line 1027, in _find_and_load
  File "<frozen importlib._bootstrap>", line 1006, in _find_and_load_unlocked
  File "<frozen importlib._bootstrap>", line 688, in _load_unlocked
  File "<frozen importlib._bootstrap_external>", line 883, in exec_module
  File "<frozen importlib._bootstrap>", line 241, in _call_with_frames_removed
  File "/home/james/abc/interview-platform-new/backend/interview_system/urls.py", line 8, in <module>
    path('api/', include('interviews.urls')),
  File "/usr/local/lib/python3.10/dist-packages/django/urls/conf.py", line 34, in include
    urlconf_module = import_module(urlconf_module)
  File "/usr/lib/python3.10/importlib/__init__.py", line 126, in import_module
    return _bootstrap._gcd_import(name[level:], package, level)
  File "<frozen importlib._bootstrap>", line 1050, in _gcd_import
  File "<frozen importlib._bootstrap>", line 1027, in _find_and_load
  File "<frozen importlib._bootstrap>", line 1006, in _find_and_load_unlocked
  File "<frozen importlib._bootstrap>", line 688, in _load_unlocked
  File "<frozen importlib._bootstrap_external>", line 883, in exec_module
  File "<frozen importlib._bootstrap>", line 241, in _call_with_frames_removed
  File "/home/james/abc/interview-platform-new/backend/interviews/urls.py", line 7, in <module>
    from .student_views import StudentInfoViewSet, EducationHistoryViewSet, CertificateViewSet
  File "/home/james/abc/interview-platform-new/backend/interviews/student_views.py", line 11, in <module>
    import pandas as pd
  File "/usr/local/lib/python3.10/dist-packages/pandas/__init__.py", line 22, in <module>
    from pandas.compat import is_numpy_dev as _is_numpy_dev  # pyright: ignore # noqa:F401
  File "/usr/local/lib/python3.10/dist-packages/pandas/compat/__init__.py", line 18, in <module>
    from pandas.compat.numpy import (
  File "/usr/local/lib/python3.10/dist-packages/pandas/compat/numpy/__init__.py", line 4, in <module>
    from pandas.util.version import Version
  File "/usr/local/lib/python3.10/dist-packages/pandas/util/__init__.py", line 2, in <module>
    from pandas.util._decorators import (  # noqa:F401
  File "/usr/local/lib/python3.10/dist-packages/pandas/util/_decorators.py", line 14, in <module>
    from pandas._libs.properties import cache_readonly
  File "/usr/local/lib/python3.10/dist-packages/pandas/_libs/__init__.py", line 13, in <module>
    from pandas._libs.interval import Interval
  File "pandas/_libs/interval.pyx", line 1, in init pandas._libs.interval
ValueError: numpy.dtype size changed, may indicate binary incompatibility. Expected 96 from C header, got 88 from PyObject
/usr/local/lib/python3.10/dist-packages/numpy/linalg/linalg.py changed, reloading.
Watching for file changes with StatReloader
Performing system checks...

System check identified no issues (0 silenced).
September 19, 2025 - 09:08:23
Django version 3.2.16, using settings 'interview_system.settings'
Starting development server at http://0.0.0.0:8000/
Quit the server with CONTROL-C.
Watching for file changes with StatReloader
Performing system checks...

System check identified no issues (0 silenced).
September 19, 2025 - 09:10:22
Django version 3.2.16, using settings 'interview_system.settings'
Starting development server at http://0.0.0.0:8000/
Quit the server with CONTROL-C.
[19/Sep/2025 09:10:29] "GET /admin/ HTTP/1.1" 200 6281
[19/Sep/2025 09:10:32] "GET /admin/interviews/studentinfo/ HTTP/1.1" 200 9208
[19/Sep/2025 09:10:32] "GET /static/admin/css/changelists.css HTTP/1.1" 304 0
[19/Sep/2025 09:10:32] "GET /static/admin/js/core.js HTTP/1.1" 304 0
[19/Sep/2025 09:10:32] "GET /static/admin/js/jquery.init.js HTTP/1.1" 304 0
[19/Sep/2025 09:10:32] "GET /static/admin/js/admin/RelatedObjectLookups.js HTTP/1.1" 304 0
[19/Sep/2025 09:10:32] "GET /admin/jsi18n/ HTTP/1.1" 200 8398
[19/Sep/2025 09:10:32] "GET /static/admin/js/vendor/jquery/jquery.js HTTP/1.1" 304 0
[19/Sep/2025 09:10:32] "GET /static/admin/js/actions.js HTTP/1.1" 304 0
[19/Sep/2025 09:10:32] "GET /static/admin/js/urlify.js HTTP/1.1" 304 0
[19/Sep/2025 09:10:32] "GET /static/admin/js/prepopulate.js HTTP/1.1" 304 0
[19/Sep/2025 09:10:32] "GET /static/admin/js/vendor/xregexp/xregexp.js HTTP/1.1" 304 0
[19/Sep/2025 09:10:32] "GET /static/admin/img/search.svg HTTP/1.1" 304 0
[19/Sep/2025 09:10:33] "GET /static/admin/img/tooltag-add.svg HTTP/1.1" 304 0
[19/Sep/2025 09:10:35] "GET /admin/interviews/studentinfo/add/ HTTP/1.1" 200 16184
[19/Sep/2025 09:10:35] "GET /static/admin/js/collapse.js HTTP/1.1" 200 1803
[19/Sep/2025 09:10:35] "GET /static/admin/js/prepopulate_init.js HTTP/1.1" 200 492
[19/Sep/2025 09:10:35] "GET /admin/jsi18n/ HTTP/1.1" 200 8398
[19/Sep/2025 09:10:35] "GET /static/admin/js/admin/DateTimeShortcuts.js HTTP/1.1" 200 19634
[19/Sep/2025 09:10:35] "GET /static/admin/css/forms.css HTTP/1.1" 200 8804
[19/Sep/2025 09:10:35] "GET /static/admin/js/calendar.js HTTP/1.1" 200 8466
[19/Sep/2025 09:10:35] "GET /static/admin/css/widgets.css HTTP/1.1" 200 11097
[19/Sep/2025 09:10:35] "GET /static/admin/js/change_form.js HTTP/1.1" 200 606
[19/Sep/2025 09:10:35] "GET /static/admin/img/icon-calendar.svg HTTP/1.1" 200 1086
[19/Sep/2025 09:11:46] "GET /static/admin/img/calendar-icons.svg HTTP/1.1" 200 1094
[19/Sep/2025 09:12:21] "POST /admin/interviews/studentinfo/add/ HTTP/1.1" 302 0
[19/Sep/2025 09:12:21] "GET /admin/interviews/studentinfo/ HTTP/1.1" 200 11852
[19/Sep/2025 09:12:21] "GET /admin/jsi18n/ HTTP/1.1" 200 8398
[19/Sep/2025 09:12:21] "GET /static/admin/img/icon-yes.svg HTTP/1.1" 200 436
[19/Sep/2025 09:12:38] "GET /admin/interviews/studentinfo/add/ HTTP/1.1" 200 16184
[19/Sep/2025 09:12:38] "GET /admin/jsi18n/ HTTP/1.1" 200 8398
[19/Sep/2025 09:14:19] "POST /admin/interviews/studentinfo/add/ HTTP/1.1" 302 0
[19/Sep/2025 09:14:19] "GET /admin/interviews/studentinfo/ HTTP/1.1" 200 12463
[19/Sep/2025 09:14:19] "GET /admin/jsi18n/ HTTP/1.1" 200 8398
[19/Sep/2025 09:14:24] "GET /admin/interviews/studentinfo/?q=%E6%9D%8E%E4%B8%80 HTTP/1.1" 200 12617
[19/Sep/2025 09:14:24] "GET /admin/jsi18n/ HTTP/1.1" 200 8398
[19/Sep/2025 09:14:27] "GET /admin/interviews/studentinfo/1/change/?_changelist_filters=q%3D%25E6%259D%258E%25E4%25B8%2580 HTTP/1.1" 200 17000
[19/Sep/2025 09:14:27] "GET /admin/jsi18n/ HTTP/1.1" 200 8398
[19/Sep/2025 10:07:39] "GET /admin/interviews/studentinfo/1/change/?_changelist_filters=q%3D%25E6%259D%258E%25E4%25B8%2580 HTTP/1.1" 200 17000
[19/Sep/2025 10:07:39] "GET /admin/jsi18n/ HTTP/1.1" 200 8398
[19/Sep/2025 10:07:47] "GET /api/dashboard/stats/ HTTP/1.1" 200 315
[19/Sep/2025 10:07:47] "GET /api/interviews/ HTTP/1.1" 200 5607
